Workbook

Sheet modelInfo
A1: pier | B1: nodeID | C1: x | D1: y | E1: z | F1: heigth | G1: height | H1: angle | I1: BA (ft) | J1: pierType | K1: hc
A2: -2 | C2: 15483.773 | D2: 561.9252 | E2: 0 | H2: =ATAN((C3-C2)/(D3-D2)) -> -0.2568923 | J2: 5C | K2: 25
A3: -1 | C3: 15233.551 | D3: 1514.4402 | E3: 0 | H3: =ATAN((C4-C3)/(D4-D3)) -> -0.29812879 | J3: 5C | K3: 25 | O3: General Dimensions
A4: 0 | C4: 14982.045 | D4: 2332.9127 | E4: 0 | F4: 24 | G4: =+F4*12 -> 288 | H4: =ATAN((C5-C4)/(D5-D4)) -> -0.35600092 | I4: 7.941 | J4: 5C | K4: 25 | O4: hb | P4: =5*12 -> 60 | Q4: in
A5: 1 | C5: 14304.67 | D5: 4154.5768 | E5: 0 | F5: 24.4 | G5: =+F5*12 -> 292.8 | H5: =ATAN((C6-C5)/(D6-D5)) -> -0.40811568 | I5: 7.941 | J5: 5C | K5: 25
A6: 2 | C6: 13867.809 | D6: 5164.9094 | E6: 0 | F6: 24.4 | G6: =+F6*12 -> 292.8 | H6: =ATAN((C7-C6)/(D7-D6)) -> -0.43546914 | I6: 7.941 | J6: 5C | K6: 25
A7: 3 | C7: 13397.981 | D7: 6174.7349 | E7: 0 | F7: 24.4 | G7: =+F7*12 -> 292.8 | H7: =ATAN((C8-C7)/(D8-D7)) -> -0.45335492 | I7: 7.941 | J7: 5C | K7: 25
A8: 4 | C8: 12914.041 | D8: 7168.0447 | E8: 0 | F8: 24.1 | G8: =+F8*12 -> 289.2 | H8: =ATAN((C9-C8)/(D9-D8)) -> -0.46239208 | I8: 7.621 | J8: 5C | K8: 25
A9: 5 | C9: 12418.367 | D9: 8162.5126 | E9: 0 | F9: 24.3 | G9: =+F9*12 -> 291.6 | H9: =ATAN((C10-C9)/(D10-D9)) -> -0.46181493 | I9: 7.495 | J9: 6C | K9: 25
A10: 6 | C10: 11743.536 | D10: 9518.3803 | E10: 0 | F10: 24.3 | G10: =+F10*12 -> 291.6 | H10: =ATAN((C11-C10)/(D11-D10)) -> -0.4539465 | I10: 7.539 | J10: 6C | K10: 25
A11: 7 | C11: 11293.73 | D11: 10440.243 | E11: 0 | F11: 23.9 | G11: =+F11*12 -> 286.8 | H11: =ATAN((C12-C11)/(D12-D11)) -> -0.44585659 | I11: 7.641 | J11: 5C | K11: 25
A12: 8 | C12: 10848.535 | D12: 11371.702 | E12: 0 | F12: 24.5 | G12: =+F12*12 -> 294 | H12: =ATAN((C13-C12)/(D13-D12)) -> -0.43630008 | I12: 7.778 | J12: 5C | K12: 25
A13: 9 | C13: 10416.261 | D13: 12298.794 | E13: 0 | F13: 24.1 | G13: =+F13*12 -> 289.2 | H13: =ATAN((C14-C13)/(D14-D13)) -> -0.42084396 | I13: 7.927 | J13: 5C | K13: 25
A14: 10 | C14: 9995.6399 | D14: 13238.55 | E14: 0 | F14: 24.7 | G14: =+F14*12 -> 296.4 | H14: =ATAN((C15-C14)/(D15-D14)) -> -0.38974164 | I14: 8.067 | J14: 6C | K14: 25
A15: 11 | C15: 9419.8268 | D15: 14640.398 | E15: 0 | F15: 24.1 | G15: =+F15*12 -> 289.2 | H15: =ATAN((C16-C15)/(D16-D15)) -> -0.35727594 | I15: 8.209 | J15: 6C | K15: 25
A16: 12 | C16: 9093.6429 | D16: 15514.192 | E16: 0 | F16: 29.3 | G16: =+F16*12 -> 351.6 | H16: =ATAN((C17-C16)/(D17-D16)) -> -0.33703608 | I16: 8.229 | J16: 5C | K16: 25
... A68: 64 | C68: 7136.8689 | D68: 68405.054 | E68: 0 | F68: 26.6 | G68: =+F68*12 -> 319.2 | H68: =ATAN((C69-C68)/(D69-D68)) -> 0.029874399 | I68: 7 | J68: 5B | K68: 25
A69: 65 | C69: 7164.1526 | D69: 69318.063 | E69: 0 | G69: =+F69*12 -> 0 | H69: =ATAN((C70-C69)/(D70-D69)) -> 0.046348538 | I69: 7 | J69: 5B | K69: 25
A70: 66 | C70: 7206.3051 | D70: 70226.879 | E70: 0 | G70: =+F70*12 -> 0 | H70: =H69 -> 0.046348538 | I70: 7 | J70: 5B | K70: 25

Sheet nodeInfo
A1: nodeID | B1: X | C1: Y | D1: Z | E1: desc
A2: 0010 | B2: =+modelInfo!C4 -> 14982.045 | C2: =+modelInfo!D4 -> 2332.9127 | D2: 0 | E2: base
A3: 0110 | B3: =+modelInfo!C5 -> 14304.67 | C3: =+modelInfo!D5 -> 4154.5768 | D3: 0 | E3: base
A4: 0210 | B4: =+modelInfo!C6 -> 13867.809 | C4: =+modelInfo!D6 -> 5164.9094 | D4: 0 | E4: base
A5: 0310 | B5: =+modelInfo!C7 -> 13397.981 | C5: =+modelInfo!D7 -> 6174.7349 | D5: 0 | E5: base
A6: 0410 | B6: =+modelInfo!C8 -> 12914.041 | C6: =+modelInfo!D8 -> 7168.0447 | D6: 0 | E6: base
A7: 0510 | B7: =+modelInfo!C9 -> 12418.367 | C7: =+modelInfo!D9 -> 8162.5126 | D7: 0 | E7: base
A8: 0610 | B8: =+modelInfo!C10 -> 11743.536 | C8: =+modelInfo!D10 -> 9518.3803 | D8: 0 | E8: base
A9: 0710 | B9: =+modelInfo!C11 -> 11293.73 | C9: =+modelInfo!D11 -> 10440.243 | D9: 0 | E9: base
A10: 0810 | B10: =+modelInfo!C12 -> 10848.535 | C10: =+modelInfo!D12 -> 11371.702 | D10: 0 | E10: base
A11: 0910 | B11: =+modelInfo!C13 -> 10416.261 | C11: =+modelInfo!D13 -> 12298.794 | D11: 0 | E11: base
A12: 1010 | B12: =+modelInfo!C14 -> 9995.6399 | C12: =+modelInfo!D14 -> 13238.55 | D12: 0 | E12: base
A13: 1110 | B13: =+modelInfo!C15 -> 9419.8268 | C13: =+modelInfo!D15 -> 14640.398 | D13: 0 | E13: base
... A66: 6410 | B66: =+modelInfo!C68 -> 7136.8689 | C66: =+modelInfo!D68 -> 68405.054 | D66: 0 | E66: base
A67: 0011 | B67: =+modelInfo!C4 -> 14982.045 | C67: =+modelInfo!D4 -> 2332.9127 | D67: =+modelInfo!G4 -> 288 | E67: top of column
A68: 0111 | B68: =+modelInfo!C5 -> 14304.67 | C68: =+modelInfo!D5 -> 4154.5768 | D68: =+modelInfo!G5 -> 292.8 | E68: top of column
A69: 0211 | B69: =+modelInfo!C6 -> 13867.809 | C69: =+modelInfo!D6 -> 5164.9094 | D69: =+modelInfo!G6 -> 292.8 | E69: top of column
A70: 0311 | B70: =+modelInfo!C7 -> 13397.981 | C70: =+modelInfo!D7 -> 6174.7349 | D70: =+modelInfo!G7 -> 292.8 | E70: top of column
A71: 0411 | B71: =+modelInfo!C8 -> 12914.041 | C71: =+modelInfo!D8 -> 7168.0447 | D71: =+modelInfo!G8 -> 289.2 | E71: top of column
A72: 0511 | B72: =+modelInfo!C9 -> 12418.367 | C72: =+modelInfo!D9 -> 8162.5126 | D72: =+modelInfo!G9 -> 291.6 | E72: top of column
A73: 0611 | B73: =+modelInfo!C10 -> 11743.536 | C73: =+modelInfo!D10 -> 9518.3803 | D73: =+modelInfo!G10 -> 291.6 | E73: top of column
A74: 0711 | B74: =+modelInfo!C11 -> 11293.73 | C74: =+modelInfo!D11 -> 10440.243 | D74: =+modelInfo!G11 -> 286.8 | E74: top of column
A75: 0811 | B75: =+modelInfo!C12 -> 10848.535 | C75: =+modelInfo!D12 -> 11371.702 | D75: =+modelInfo!G12 -> 294 | E75: top of column
A76: 0911 | B76: =+modelInfo!C13 -> 10416.261 | C76: =+modelInfo!D13 -> 12298.794 | D76: =+modelInfo!G13 -> 289.2 | E76: top of column
A77: 1011 | B77: =+modelInfo!C14 -> 9995.6399 | C77: =+modelInfo!D14 -> 13238.55 | D77: =+modelInfo!G14 -> 296.4 | E77: top of column
A78: 1111 | B78: =+modelInfo!C15 -> 9419.8268 | C78: =+modelInfo!D15 -> 14640.398 | D78: =+modelInfo!G15 -> 289.2 | E78: top of column
... A131: 6411 | B131: =+modelInfo!C68 -> 7136.8689 | C131: =+modelInfo!D68 -> 68405.054 | D131: =+modelInfo!G68 -> 319.2 | E131: top of column
A132: 0021 | B132: =+modelInfo!C4 -> 14982.045 | C132: =+modelInfo!D4 -> 2332.9127 | D132: =+modelInfo!G4 + modelInfo!$P$4 -> 348 | E132: top of beam
A133: 0121 | B133: =+modelInfo!C5 -> 14304.67 | C133: =+modelInfo!D5 -> 4154.5768 | D133: =+modelInfo!G5 + modelInfo!$P$4 -> 352.8 | E133: top of beam
A134: 0221 | B134: =+modelInfo!C6 -> 13867.809 | C134: =+modelInfo!D6 -> 5164.9094 | D134: =+modelInfo!G6 + modelInfo!$P$4 -> 352.8 | E134: top of beam
A135: 0321 | B135: =+modelInfo!C7 -> 13397.981 | C135: =+modelInfo!D7 -> 6174.7349 | D135: =+modelInfo!G7 + modelInfo!$P$4 -> 352.8 | E135: top of beam
A136: 0421 | B136: =+modelInfo!C8 -> 12914.041 | C136: =+modelInfo!D8 -> 7168.0447 | D136: =+modelInfo!G8 + modelInfo!$P$4 -> 349.2 | E136: top of beam
A137: 0521 | B137: =+modelInfo!C9 -> 12418.367 | C137: =+modelInfo!D9 -> 8162.5126 | D137: =+modelInfo!G9 + modelInfo!$P$4 -> 351.6 | E137: top of beam
A138: 0621 | B138: =+modelInfo!C10 -> 11743.536 | C138: =+modelInfo!D10 -> 9518.3803 | D138: =+modelInfo!G10 + modelInfo!$P$4 -> 351.6 | E138: top of beam
A139: 0721 | B139: =+modelInfo!C11 -> 11293.73 | C139: =+modelInfo!D11 -> 10440.243 | D139: =+modelInfo!G11 + modelInfo!$P$4 -> 346.8 | E139: top of beam
A140: 0821 | B140: =+modelInfo!C12 -> 10848.535 | C140: =+modelInfo!D12 -> 11371.702 | D140: =+modelInfo!G12 + modelInfo!$P$4 -> 354 | E140: top of beam
A141: 0921 | B141: =+modelInfo!C13 -> 10416.261 | C141: =+modelInfo!D13 -> 12298.794 | D141: =+modelInfo!G13 + modelInfo!$P$4 -> 349.2 | E141: top of beam
A142: 1021 | B142: =+modelInfo!C14 -> 9995.6399 | C142: =+modelInfo!D14 -> 13238.55 | D142: =+modelInfo!G14 + modelInfo!$P$4 -> 356.4 | E142: top of beam
A143: 1121 | B143: =+modelInfo!C15 -> 9419.8268 | C143: =+modelInfo!D15 -> 14640.398 | D143: =+modelInfo!G15 + modelInfo!$P$4 -> 349.2 | E143: top of beam
... A196: 6421 | B196: =+modelInfo!C68 -> 7136.8689 | C196: =+modelInfo!D68 -> 68405.054 | D196: =+modelInfo!G68 + modelInfo!$P$4 -> 379.2 | E196: top of beam
...

Sheet elements
A1: eleTag | B1: nodei | C1: nodej | D1: type | E1: ptype | F1: hc
A2: 0001 | B2: =+nodeInfo!A2 -> 0010 | C2: =+nodeInfo!A67 -> 0011 | D2: pierCol | E2: =modelInfo!J4 -> 5C | F2: 25
A3: 0101 | B3: =+nodeInfo!A3 -> 0110 | C3: =+nodeInfo!A68 -> 0111 | D3: pierCol | E3: =modelInfo!J5 -> 5C | F3: 25
A4: 0201 | B4: =+nodeInfo!A4 -> 0210 | C4: =+nodeInfo!A69 -> 0211 | D4: pierCol | E4: =modelInfo!J6 -> 5C | F4: 25
A5: 0301 | B5: =+nodeInfo!A5 -> 0310 | C5: =+nodeInfo!A70 -> 0311 | D5: pierCol | E5: =modelInfo!J7 -> 5C | F5: 25
A6: 0401 | B6: =+nodeInfo!A6 -> 0410 | C6: =+nodeInfo!A71 -> 0411 | D6: pierCol | E6: =modelInfo!J8 -> 5C | F6: 25
A7: 0501 | B7: =+nodeInfo!A7 -> 0510 | C7: =+nodeInfo!A72 -> 0511 | D7: pierCol | E7: =modelInfo!J9 -> 6C | F7: 25
A8: 0601 | B8: =+nodeInfo!A8 -> 0610 | C8: =+nodeInfo!A73 -> 0611 | D8: pierCol | E8: =modelInfo!J10 -> 6C | F8: 25
A9: 0701 | B9: =+nodeInfo!A9 -> 0710 | C9: =+nodeInfo!A74 -> 0711 | D9: pierCol | E9: =modelInfo!J11 -> 5C | F9: 25
A10: 0801 | B10: =+nodeInfo!A10 -> 0810 | C10: =+nodeInfo!A75 -> 0811 | D10: pierCol | E10: =modelInfo!J12 -> 5C | F10: 25
A11: 0901 | B11: =+nodeInfo!A11 -> 0910 | C11: =+nodeInfo!A76 -> 0911 | D11: pierCol | E11: =modelInfo!J13 -> 5C | F11: 25
A12: 1001 | B12: =+nodeInfo!A12 -> 1010 | C12: =+nodeInfo!A77 -> 1011 | D12: pierCol | E12: =modelInfo!J14 -> 6C | F12: 25
A13: 1101 | B13: =+nodeInfo!A13 -> 1110 | C13: =+nodeInfo!A78 -> 1111 | D13: pierCol | E13: =modelInfo!J15 -> 6C | F13: 25
... A66: 6401 | B66: =+nodeInfo!A66 -> 6410 | C66: =+nodeInfo!A131 -> 6411 | D66: pierCol | E66: =modelInfo!J68 -> 5B | F66: 25
A67: 0002 | B67: =+nodeInfo!A67 -> 0011 | C67: =+nodeInfo!A132 -> 0021 | D67: pierRigid
A68: 0102 | B68: =+nodeInfo!A68 -> 0111 | C68: =+nodeInfo!A133 -> 0121 | D68: pierRigid
A69: 0202 | B69: =+nodeInfo!A69 -> 0211 | C69: =+nodeInfo!A134 -> 0221 | D69: pierRigid
A70: 0302 | B70: =+nodeInfo!A70 -> 0311 | C70: =+nodeInfo!A135 -> 0321 | D70: pierRigid
A71: 0402 | B71: =+nodeInfo!A71 -> 0411 | C71: =+nodeInfo!A136 -> 0421 | D71: pierRigid
A72: 0502 | B72: =+nodeInfo!A72 -> 0511 | C72: =+nodeInfo!A137 -> 0521 | D72: pierRigid
A73: 0602 | B73: =+nodeInfo!A73 -> 0611 | C73: =+nodeInfo!A138 -> 0621 | D73: pierRigid
A74: 0702 | B74: =+nodeInfo!A74 -> 0711 | C74: =+nodeInfo!A139 -> 0721 | D74: pierRigid
A75: 0802 | B75: =+nodeInfo!A75 -> 0811 | C75: =+nodeInfo!A140 -> 0821 | D75: pierRigid
A76: 0902 | B76: =+nodeInfo!A76 -> 0911 | C76: =+nodeInfo!A141 -> 0921 | D76: pierRigid
A77: 1002 | B77: =+nodeInfo!A77 -> 1011 | C77: =+nodeInfo!A142 -> 1021 | D77: pierRigid
A78: 1102 | B78: =+nodeInfo!A78 -> 1111 | C78: =+nodeInfo!A143 -> 1121 | D78: pierRigid
... A131: 6402 | B131: =+nodeInfo!A131 -> 6411 | C131: =+nodeInfo!A196 -> 6421 | D131: pierRigid
A132: 0003 | B132: =+nodeInfo!A197 -> 0002 | C132: =+nodeInfo!A132 -> 0021 | D132: westRigid
A133: 0103 | B133: =+nodeInfo!A198 -> 0102 | C133: =+nodeInfo!A133 -> 0121 | D133: westRigid
A134: 0203 | B134: =+nodeInfo!A199 -> 0202 | C134: =+nodeInfo!A134 -> 0221 | D134: westRigid
A135: 0303 | B135: =+nodeInfo!A200 -> 0302 | C135: =+nodeInfo!A135 -> 0321 | D135: westRigid
A136: 0403 | B136: =+nodeInfo!A201 -> 0402 | C136: =+nodeInfo!A136 -> 0421 | D136: westRigid
A137: 0503 | B137: =+nodeInfo!A202 -> 0502 | C137: =+nodeInfo!A137 -> 0521 | D137: westRigid
A138: 0603 | B138: =+nodeInfo!A203 -> 0602 | C138: =+nodeInfo!A138 -> 0621 | D138: westRigid
A139: 0703 | B139: =+nodeInfo!A204 -> 0702 | C139: =+nodeInfo!A139 -> 0721 | D139: westRigid
A140: 0803 | B140: =+nodeInfo!A205 -> 0802 | C140: =+nodeInfo!A140 -> 0821 | D140: westRigid
A141: 0903 | B141: =+nodeInfo!A206 -> 0902 | C141: =+nodeInfo!A141 -> 0921 | D141: westRigid
A142: 1003 | B142: =+nodeInfo!A207 -> 1002 | C142: =+nodeInfo!A142 -> 1021 | D142: westRigid
A143: 1103 | B143: =+nodeInfo!A208 -> 1102 | C143: =+nodeInfo!A143 -> 1121 | D143: westRigid
... A196: 6403 | B196: =+nodeInfo!A261 -> 6402 | C196: =+nodeInfo!A196 -> 6421 | D196: westRigid
...
